[Running in Docker container]
[Starting...]
Clustering by tree_diff
Invalid assignment name, must be one of ['Filesystem', 'DocDiff', 'Nile']
Clustering data from Docdiff 	
	 This may take some time...
Traceback (most recent call last):
  File "/usr/lib/python3.8/runpy.py", line 194, in _run_module_as_main
    return _run_code(code, main_globals, None,
  File "/usr/lib/python3.8/runpy.py", line 87, in _run_code
    exec(code, run_globals)
  File "/src/clustering.py", line 84, in <module>
    _, labels_true, __, code = read_excel_file(file, s)
  File "/src/clustering.py", line 10, in read_excel_file
    df = pd.read_excel(f, sheet_name=sheetname, engine="odf")
  File "/usr/local/lib/python3.8/dist-packages/pandas/util/_decorators.py", line 311, in wrapper
    return func(*args, **kwargs)
  File "/usr/local/lib/python3.8/dist-packages/pandas/io/excel/_base.py", line 465, in read_excel
    data = io.parse(
  File "/usr/local/lib/python3.8/dist-packages/pandas/io/excel/_base.py", line 1458, in parse
    return self._reader.parse(
  File "/usr/local/lib/python3.8/dist-packages/pandas/io/excel/_base.py", line 634, in parse
    sheet = self.get_sheet_by_name(asheetname)
  File "/usr/local/lib/python3.8/dist-packages/pandas/io/excel/_odfreader.py", line 72, in get_sheet_by_name
    self.raise_if_bad_sheet_by_name(name)
  File "/usr/local/lib/python3.8/dist-packages/pandas/io/excel/_base.py", line 570, in raise_if_bad_sheet_by_name
    raise ValueError(f"Worksheet named '{name}' not found")
ValueError: Worksheet named 'Docdiff' not found
